Workbook

Sheet Index
A1: =Assumptions!B2 -> Infosys Limited
B3: 📥 INPUTS
B5: Assumptions
B6: P&L Input
B7: BS Input
B8: CF Input
B9: Market Data
B10: Equity Beta
B11: Comps Data
B14: 📊Calculation & Analysis
B16: Common Sizing
B17: Revenue Build-up
B18: Working Capital
... B27: FAS

Sheet Assumptions
B2: Infosys Limited
B6: Company Description | C6: Infosys Limited
B7: ISIN Code | C7: INE009A01021
B8: Sector Name | C8: Information Technology
B9: Industry | C9: Computers - Software & Consulting
B10: Exchange Name | C10: BSE: 500209, NSE: INFY
B11: Website | C11: https://www.infosys.com
B12: Company Description | C12: Infosys Limited is a global leader in AI-first business consulting and technology services. Established in 1981, Infosys helps enterprises across 59 countries navigate digital transformation through AI, cloud, digital services, consulting and technology solutions. With over 3.25 lakh employees and 1,965 active clients, the company focuses on enterprise transformation, AI-first services, cloud capabilities and digital innovation.
B13: Current Market Price | C13: 1161.2
B16: Scenario | D16: Case
B17: Base case | D17: =IF(B17="Best case",1,IF(B17="Base case",2,3)) -> 2
B20: Company data
B21: Particulars | D21: Amount
B22: No of Outstanding shares | C22: Nos | D22: 4038289901
B23: Face Value per share | C23: Rs. | D23: 5
B24: Current Market Price | C24: Rs. | D24: =C13 -> 1161.2
B25: Market Capitalisation | C25: INR in Crs | D25: =D22*D24/10^7 -> 468926.22
B28: Assumptions
B29: Perpetual Growth rate | C29: % | D29: 0.04
B30: 10 year Bond yield rate | C30: % | D30: 0.07077
B31: Interest rate | C31: % | D31: ='Cost Buildup'!G35*(1-'Cost Buildup'!G37) -> 0.033409756
B32: Bull Case Tapering Rate (p.a.) | C32: % | D32: 0.01
I33: Revenue in Crs
B34: Company Revenue by Geography
B35: Year | C35: ='Revenue Buildup'!B38 -> North America | E35: ='Revenue Buildup'!B44 -> Europe | G35: ='Revenue Buildup'!B50 -> India | I35: Rest of the World
B36: 2022 | C36: ='Revenue Buildup'!C38 -> 75058 | E36: ='Revenue Buildup'!C44 -> 30129 | G36: ='Revenue Buildup'!C50 -> 3585 | I36: ='Revenue Buildup'!C56 -> 12869
B37: =B36+1 -> 2023 | C37: ='Revenue Buildup'!D38 -> 90724 | E37: ='Revenue Buildup'!D44 -> 37675 | G37: ='Revenue Buildup'!D50 -> 3861 | I37: ='Revenue Buildup'!D56 -> 14507
B38: =B37+1 -> 2024 | C38: ='Revenue Buildup'!E38 -> 92411 | E38: ='Revenue Buildup'!E44 -> 42267 | G38: ='Revenue Buildup'!E50 -> 3881 | I38: ='Revenue Buildup'!E56 -> 15111
B39: =B38+1 -> 2025 | C39: ='Revenue Buildup'!F38 -> 94397 | E39: ='Revenue Buildup'!F44 -> 48595 | G39: ='Revenue Buildup'!F50 -> 5014 | I39: ='Revenue Buildup'!F56 -> 14984
B40: =B39+1 -> 2026 | C40: ='Revenue Buildup'!G38 -> 100167 | E40: ='Revenue Buildup'!G44 -> 57454 | G40: ='Revenue Buildup'!G50 -> 5102 | I40: ='Revenue Buildup'!G56 -> 15927
B46: Headings | C46: Reference | D46: Assumptions
B47: Revenue Buildup | C47: H15:Q15 | D47: Revenue is forecast using the historical average growth rate as the base assumption. The Bull Case assumes a higher growth rate than the Base Case, while the Bear Case assumes a lower growth rate. The growth rate under the scenarios is tapered by 1% annually to reflect a gradual moderation in growth over the forecast period.
C48: H18:Q18 H22:Q22 | D48: Other Income is forecast at 2% of Revenue from Operations based on the historical trend. Exceptional Items were reported only in FY2026 at approximately 1% of Revenue from Operations. For the forecast period, Exceptional Items are assumed at 0.25% of Revenue from Operations to reflect a lower impact compared with FY2026.
B49: Cost Buildup | C49: H13:Q13 H31:Q31 | D49: Employee Cost and other operating expenses are forecast as a percentage of Revenue from Operations using the historical average ratio. The average historical cost-to-revenue ratio is applied consistently throughout the forecast period.
C50: H34:Q34 | D50: Finance Cost is forecast as a percentage of period-end Lease Liabilities. The historical Finance Cost-to-Lease Liabilities ratio is calculated for the past five years, and the average historical ratio of approximately 4% is applied throughout the forecast period.
C51: H37:Q37 | D51: The Effective Tax Rate is forecast based on the historical tax rate, with an annual increase of 0.3 percentage points from FY2027 onwards. The FY2027 tax rate is derived by adding 0.3% to the FY2026 rate, and the same incremental approach is followed throughout the forecast period.
B52: FAS | C52: H173:Q173 | D52: Figures of the year 2025 are used to forecast the additions, disposals and depreciation of Fixed assets, Intangibles and ROU assets with 4% growth rate for the 1st projected year and for every 3 years.
C53: H165:Q165 | D53: Capital WIP for FY2027 is based on the average historical increase in Capital WIP. From FY2028 onwards, the annual increase in Capital WIP is grown by 0.5% each year.
B54: BS Items | C54: I13:R13 I54:R54 | D54: Balance Sheet line items are forecast as a percentage of Revenue from Operations using their respective five-year historical average ratios.
B55: Working Capital | C55: H11:Q11 H12:Q12 | D55: Trade Receivables and Trade Payables are projected as a fixed percentage of revenue, based on the average proportions observed over the last five audited years.
...

Sheet P&L Input
B2: Infosys Limited
F6: (INR in Crores)
B7: P&L Input
B8: Particulars | C8: 2022 | D8: =C8+1 -> 2023 | E8: =D8+1 -> 2024 | F8: =E8+1 -> 2025 | G8: =F8+1 -> 2026
C9: Audited | D9: Audited | E9: Audited | F9: Audited | G9: Audited
B11: Revenue from Operations | C11: 121641 | D11: 146767 | E11: 153670 | F11: 162990 | G11: 178650
B12: Other Income, net | C12: 2295 | D12: 2701 | E12: 4711 | F12: 3600 | G12: 4322
B14: Total Income | C14: =SUM(C11:C12) -> 123936 | D14: =SUM(D11:D12) -> 149468 | E14: =SUM(E11:E12) -> 158381 | F14: =SUM(F11:F12) -> 166590 | G14: =SUM(G11:G12) -> 182972
B16: Expenses
B17: Employee benefit expenses | C17: 63986 | D17: 78359 | E17: 82620 | F17: 85950 | G17: 95094
B18: Cost of technical sub-contractors | C18: 12606 | D18: 14062 | E18: 12232 | F18: 12937 | G18: 15421
B19: Travel expenses | C19: 827 | D19: 1525 | E19: 1759 | F19: 1894 | G19: 2097
B20: Cost of software packages and others | C20: 6811 | D20: 10902 | E20: 13515 | F20: 15911 | G20: 15722
B21: Communication expenses | C21: 611 | D21: 713 | E21: 677 | F21: 620 | G21: 603
B22: Consultancy and professional charges | C22: 1885 | D22: 1684 | E22: 1726 | F22: 1655 | G22: 2090
B23: Other expenses | C23: 3424 | D23: 4392 | E23: 4716 | F23: 4787 | G23: 5343
B24: Total Expenses | C24: =SUM(C17:C23) -> 90150 | D24: =SUM(D17:D23) -> 111637 | E24: =SUM(E17:E23) -> 117245 | F24: =SUM(F17:F23) -> 123754 | G24: =SUM(G17:G23) -> 136370
B26: EBITDA | C26: =C14-C24 -> 33786 | D26: =D14-D24 -> 37831 | E26: =E14-E24 -> 41136 | F26: =F14-F24 -> 42836 | G26: =G14-G24 -> 46602
B28: Depreciation and Amortisation Expenses | C28: 3476 | D28: 4225 | E28: 4678 | F28: 4812 | G28: 4902
B30: EBIT | C30: =C26-C28 -> 30310 | D30: =D26-D28 -> 33606 | E30: =E26-E28 -> 36458 | F30: =F26-F28 -> 38024 | G30: =G26-G28 -> 41700
B32: Finance Costs | C32: 200 | D32: 284 | E32: 470 | F32: 416 | G32: 416
B34: Profit before exceptional items | C34: =C30-C32 -> 30110 | D34: =D30-D32 -> 33322 | E34: =E30-E32 -> 35988 | F34: =F30-F32 -> 37608 | G34: =G30-G32 -> 41284
B36: Exceptional items | C36: 0 | D36: 0 | E36: 0 | F36: 0 | G36: 1289
B38: Profit before Tax | C38: =C34-C36 -> 30110 | D38: =D34-D36 -> 33322 | E38: =E34-E36 -> 35988 | F38: =F34-F36 -> 37608 | G38: =G34-G36 -> 39995
B40: Taxes (Current + Deferred) | C40: 7964 | D40: 9214 | E40: 9740 | F40: 10858 | G40: 10521
B42: Net Profit | C42: =C38-C40 -> 22146 | D42: =D38-D40 -> 24108 | E42: =E38-E40 -> 26248 | F42: =F38-F40 -> 26750 | G42: =G38-G40 -> 29474
B45: KPIs
B46: Revenue % (y-o-y) | C46: - | D46: =D11/C11-1 -> 0.20655864 | E46: =E11/D11-1 -> 0.047033734 | F46: =F11/E11-1 -> 0.060649444 | G46: =G11/F11-1 -> 0.096079514
B47: EBITDA% | C47: =C26/C14 -> 0.27260844 | D47: =D26/D14 -> 0.25310434 | E47: =E26/E14 -> 0.25972812 | F47: =F26/F14 -> 0.25713428 | G47: =G26/G14 -> 0.25469471
B48: EBIT % | C48: =C30/C14 -> 0.24456171 | D48: =D30/D14 -> 0.22483742 | E48: =E30/E14 -> 0.23019175 | F48: =F30/F14 -> 0.22824899 | G48: =G30/G14 -> 0.22790372
B49: NP % | C49: =C42/C14 -> 0.178689 | D49: =D42/D14 -> 0.16129205 | E49: =E42/E14 -> 0.16572695 | F49: =F42/F14 -> 0.16057386 | G49: =G42/G14 -> 0.16108476
B50: ROA | C50: 0.18786105 | D50: 0.19161315 | E50: 0.1904596 | F50: 0.17964715 | G50: 0.18897587
B51: Asset Turnover | C51: 1.0318616 | D51: 1.166521 | E51: 1.1150536 | F51: 1.0946052 | G51: 1.1454346
B52: Assets / Equity | C52: 1.5565253 | D52: 1.6599512 | E52: 1.5579069 | F52: 1.5478 | G52: 1.6717258
B53: ROE | C53: =C49*C51*C52 -> 0.28699573 | D53: =D49*D51*D52 -> 0.31232074 | E53: =E49*E51*E52 -> 0.28789252 | F53: =F49*F51*F52 -> 0.27204904 | G53: =G49*G51*G52 -> 0.30845356

Sheet BS Input
B2: Infosys Limited
B6: Balance Sheet Input
B7: Particulars | D7: 2022 | E7: =D7+1 -> 2023 | F7: =E7+1 -> 2024 | G7: =F7+1 -> 2025 | H7: =G7+1 -> 2026
D8: Audited | E8: Audited | F8: Audited | G8: Audited | H8: Audited
B9: ASSETS
B11: Non-Current Assets
C12: PPE | D12: 13075 | E12: 13346 | F12: 12370 | G12: 11778 | H12: 12651
C13: ROU Assets | D13: 4823 | E13: 6882 | F13: 6552 | G13: 6311 | H13: 6177
C14: Capital WIP | D14: 416 | E14: 288 | F14: 293 | G14: 814 | H14: 526
C15: Goodwill | D15: 6195 | E15: 7248 | F15: 7303 | G15: 10106 | H15: 12117
C16: Other Intangible assets | D16: 1707 | E16: 1749 | F16: 1397 | G16: 2766 | H16: 2825
C17: Financial Assets
C18: Investments | D18: 13651 | E18: 12569 | F18: 11708 | G18: 11059 | H18: 8930
C19: Loans | D19: 34 | E19: 39 | F19: 34 | G19: 16 | H19: 6
C20: Other financial assets | D20: 1460 | E20: 2798 | F20: 3105 | G20: 3511 | H20: 2776
C21: Deferred Tax Assets(net) | D21: 1212 | E21: 1245 | F21: 454 | G21: 1108 | H21: 2264
C22: Income tax assets (net) | D22: 6098 | E22: 6453 | F22: 3045 | G22: 1622 | H22: 666
C23: Other non-current assets | D23: 2029 | E23: 2318 | F23: 2121 | G23: 2713 | H23: 3540
B25: Total Non-current assets | D25: =SUM(D12:D16,D18:D23) -> 50700 | E25: =SUM(E12:E16,E18:E23) -> 54935 | F25: =SUM(F12:F16,F18:F23) -> 48382 | G25: =SUM(G12:G16,G18:G23) -> 51804 | H25: =SUM(H12:H16,H18:H23) -> 52478
B27: Current Assets
C28: Financial Assets
C29: Investments | D29: 6673 | E29: 6909 | F29: 12915 | G29: 12482 | H29: 12950
C30: Trade Receivables | D30: 22698 | E30: 25424 | F30: 30193 | G30: 31158 | H30: 35234
C31: Cash & Cash Equivalents | D31: 17472 | E31: 12173 | F31: 14786 | G31: 24455 | H31: 22201
C32: Loans | D32: 248 | E32: 289 | F32: 248 | G32: 249 | H32: 234
C33: Other financial assets | D33: 8727 | E33: 11604 | F33: 12085 | G33: 13840 | H33: 15890
C34: Income tax assets (net) | D34: 54 | E34: 6 | F34: 6397 | G34: 2975 | H34: 1835
C35: Other current assets | D35: 11313 | E35: 14476 | F35: 12808 | G35: 11940 | H35: 15145
B37: Total Current Assets | D37: =SUM(D29:D35) -> 67185 | E37: =SUM(E29:E35) -> 70881 | F37: =SUM(F29:F35) -> 89432 | G37: =SUM(G29:G35) -> 97099 | H37: =SUM(H29:H35) -> 103489
B39: TOTAL | D39: =D25+D37 -> 117885 | E39: =E25+E37 -> 125816 | F39: =F25+F37 -> 137814 | G39: =G25+G37 -> 148903 | H39: =H25+H37 -> 155967
B41: EQUITY AND LIABILITIES
B43: Shareholder Funds
C44: Equity Share Capital | D44: 2098 | E44: 2069 | F44: 2071 | G44: 2073 | H44: 2024
C45: Other Equity | D45: 73252 | E45: 73338 | F45: 86045 | G45: 93745 | H45: 90828
C46: Non-Controlling Interest | D46: 386 | E46: 388 | F46: 345 | G46: 385 | H46: 445
B48: Total Equity | D48: =SUM(D44:D46) -> 75736 | E48: =SUM(E44:E46) -> 75795 | F48: =SUM(F44:F46) -> 88461 | G48: =SUM(G44:G46) -> 96203 | H48: =SUM(H44:H46) -> 93297
B50: Non-current liabilities
C51: Financial Liabilities
C52: Lease Liabilities | D52: 4602 | E52: 7057 | F52: 6400 | G52: 5772 | H52: 6016
C53: Other financial liabilities | D53: 2337 | E53: 2058 | F53: 2130 | G53: 2141 | H53: 2092
...

Sheet CF Input
B2: Infosys Limited
G6: (INR in Crores)
B7: Cash Flow Input
B8: Particulars | D8: ='BS Input'!D7 -> 2022 | E8: ='BS Input'!E7 -> 2023 | F8: ='BS Input'!F7 -> 2024 | G8: ='BS Input'!G7 -> 2025 | H8: ='BS Input'!H7 -> 2026
D9: Audited | E9: Audited | F9: Audited | G9: Audited | H9: Audited
B11: Cash flow from operating activities
C12: Profit for the year | D12: 22146 | E12: 24108 | F12: 26248 | G12: 26750 | H12: 29474
C13: Adjustments to reconcile net profit to net cash provided by operating activities:
C14: – Income tax expense | D14: 7964 | E14: 9214 | F14: 9740 | G14: 10858 | H14: 10521
C15: – Depreciation and amortization | D15: 3476 | E15: 4225 | F15: 4678 | G15: 4812 | H15: 4902
C16: – Interest and dividend income | D16: -1645 | E16: -1817 | F16: -2067 | G16: -2570 | H16: -2630
C17: – Finance cost | D17: 200 | E17: 284 | F17: 470 | G17: 416 | H17: 416
C18: – Impairment loss recognized / (reversed) under expected credit loss model | D18: 170 | E18: 283 | F18: 121 | G18: 48 | H18: 33
C19: – Exchange differences on translation of assets and liabilities, net | D19: 119 | E19: 161 | F19: 76 | G19: 79 | H19: 954
C20: – Stock compensation expense | D20: 415 | E20: 519 | F20: 652 | G20: 802 | H20: 952
C21: – Interest receivable on income tax refund | D21: 0 | E21: 0 | F21: -1934 | G21: -327 | H21: -63
C22: – Provision for post-sales client support | D22: 0 | E22: 0 | F22: 75 | G22: -110 | H22: -167
C23: – Other adjustments | D23: 76 | E23: 628 | F23: 1464 | G23: 833 | H23: 881
B25: Changes in assets and liabilities
C26: – Trade receivables and unbilled revenue | D26: -7937 | E26: -7076 | F26: -2667 | G26: -1769 | H26: -5177
C27: – Loans, other financial assets and other assets | D27: -1914 | E27: -3108 | F27: -1172 | G27: -1024 | H27: -2645
C28: – Trade payables | D28: 1489 | E28: -279 | F28: 91 | G28: 176 | H28: -26
C29: – Other financial liabilities, other liabilities and provisions | D29: 6938 | E29: 4119 | F29: -1334 | G29: 2322 | H29: 5209
B31: Cash generated from operations | D31: =SUM(D12:D29) -> 31497 | E31: =SUM(E12:E29) -> 31261 | F31: =SUM(F12:F29) -> 34441 | G31: =SUM(G12:G29) -> 41296 | H31: =SUM(H12:H29) -> 42634
C32: – Income taxes paid | D32: -7612 | E32: -8794 | F32: -9231 | G32: -5602 | H32: -8648
B34: Net cash generated by operating activities | D34: =D31+D32 -> 23885 | E34: =E31+E32 -> 22467 | F34: =F31+F32 -> 25210 | G34: =G31+G32 -> 35694 | H34: =H31+H32 -> 33986
B36: Cash flows from investing activities
C37: – Expenditure on property, plant and equipment and intangibles | D37: -2161 | E37: -2579 | F37: -2201 | G37: -2237 | H37: -2727
C38: – Deposits placed with corporation | D38: -906 | E38: -996 | F38: -847 | G38: -1225 | H38: -944
C39: – Redemption of deposits placed with corporation | D39: 753 | E39: 762 | F39: 710 | G39: 776 | H39: 725
C40: – Interest and dividend received | D40: 1898 | E40: 1525 | F40: 1768 | G40: 2040 | H40: 2713
C41: – Payment towards acquisition of business, net of cash acquired | D41: 0 | E41: -910 | F41: 0 | G41: -3155 | H41: -637
C42: – Payment of contingent consideration pertaining to acquisition of business | D42: -53 | E42: -60 | F42: -101 | G42: 0 | H42: -13
C43: – Escrow and other deposits pertaining to buyback | D43: -420 | E43: -483 | F43: 0 | G43: 0 | H43: -1815
C44: – Redemption of escrow and other deposits pertaining to buyback | D44: 420 | E44: 483 | F44: 0 | G44: 0 | H44: 1815
C45: – Other receipts | D45: 67 | E45: 71 | F45: 128 | G45: 10 | H45: 15
C46: – Other payments | D46: -22 | E46: 0 | F46: 0 | G46: 0 | H46: 0
C48: Payments to acquire investments:
C49: Tax-free bonds and government bonds | D49: 0 | E49: -27 | F49: 0 | G49: -2 | H49: -153
C50: mutual fund units | D50: -54064 | E50: -70631 | F50: -66191 | G50: -73048 | H50: -72878
...

Sheet Common Sizing
B2: Infosys Limited
B7: Common Sizing
B8: Particulars | D8: ='BS Input'!D7 -> 2022 | E8: ='BS Input'!E7 -> 2023 | F8: ='BS Input'!F7 -> 2024 | G8: ='BS Input'!G7 -> 2025 | H8: ='BS Input'!H7 -> 2026
D9: Audited | E9: Audited | F9: Audited | G9: Audited | H9: Audited
C11: Revenue from Operations | D11: ='P&L Input'!C11/'P&L Input'!C$14 -> 0.98148238 | E11: ='P&L Input'!D11/'P&L Input'!D$14 -> 0.98192924 | F11: ='P&L Input'!E11/'P&L Input'!E$14 -> 0.97025527 | G11: ='P&L Input'!F11/'P&L Input'!F$14 -> 0.97839006 | H11: ='P&L Input'!G11/'P&L Input'!G$14 -> 0.9763789
C12: Other Operating Revenues | D12: ='P&L Input'!C12/'P&L Input'!C$14 -> 0.018517622 | E12: ='P&L Input'!D12/'P&L Input'!D$14 -> 0.018070758 | F12: ='P&L Input'!E12/'P&L Input'!E$14 -> 0.029744729 | G12: ='P&L Input'!F12/'P&L Input'!F$14 -> 0.021609941 | H12: ='P&L Input'!G12/'P&L Input'!G$14 -> 0.0236211
B14: Total Income | D14: ='P&L Input'!C14/'P&L Input'!C$14 -> 1 | E14: ='P&L Input'!D14/'P&L Input'!D$14 -> 1 | F14: ='P&L Input'!E14/'P&L Input'!E$14 -> 1 | G14: ='P&L Input'!F14/'P&L Input'!F$14 -> 1 | H14: ='P&L Input'!G14/'P&L Input'!G$14 -> 1
C16: Expenses
C17: Employee Benefit Expenses | D17: ='P&L Input'!C17/'P&L Input'!C$14 -> 0.5162826 | E17: ='P&L Input'!D17/'P&L Input'!D$14 -> 0.52425268 | F17: ='P&L Input'!E17/'P&L Input'!E$14 -> 0.52165348 | G17: ='P&L Input'!F17/'P&L Input'!F$14 -> 0.51593733 | H17: ='P&L Input'!G17/'P&L Input'!G$14 -> 0.51971886
C18: Other expenses | D18: ='P&L Input'!C18/'P&L Input'!C$14 -> 0.10171379 | E18: ='P&L Input'!D18/'P&L Input'!D$14 -> 0.094080338 | F18: ='P&L Input'!E18/'P&L Input'!E$14 -> 0.077231486 | G18: ='P&L Input'!F18/'P&L Input'!F$14 -> 0.077657723 | H18: ='P&L Input'!G18/'P&L Input'!G$14 -> 0.084280655
B20: Total Expenses | D20: ='P&L Input'!C20/'P&L Input'!C$14 -> 0.054955784 | E20: ='P&L Input'!D20/'P&L Input'!D$14 -> 0.072938689 | F20: ='P&L Input'!E20/'P&L Input'!E$14 -> 0.085332205 | G20: ='P&L Input'!F20/'P&L Input'!F$14 -> 0.095509935 | H20: ='P&L Input'!G20/'P&L Input'!G$14 -> 0.085925715
C22: EBITDA | D22: ='P&L Input'!C22/'P&L Input'!C$14 -> 0.015209463 | E22: ='P&L Input'!D22/'P&L Input'!D$14 -> 0.011266626 | F22: ='P&L Input'!E22/'P&L Input'!E$14 -> 0.010897772 | G22: ='P&L Input'!F22/'P&L Input'!F$14 -> 0.0099345699 | H22: ='P&L Input'!G22/'P&L Input'!G$14 -> 0.011422513
C23: Depreciation & Amortisation | D23: ='P&L Input'!C24/'P&L Input'!C$14 -> 0.72739156 | E23: ='P&L Input'!D24/'P&L Input'!D$14 -> 0.74689566 | F23: ='P&L Input'!E24/'P&L Input'!E$14 -> 0.74027188 | G23: ='P&L Input'!F24/'P&L Input'!F$14 -> 0.74286572 | H23: ='P&L Input'!G24/'P&L Input'!G$14 -> 0.74530529
C24: EBIT | D24: ='P&L Input'!C26/'P&L Input'!C$14 -> 0.27260844 | E24: ='P&L Input'!D26/'P&L Input'!D$14 -> 0.25310434 | F24: ='P&L Input'!E26/'P&L Input'!E$14 -> 0.25972812 | G24: ='P&L Input'!F26/'P&L Input'!F$14 -> 0.25713428 | H24: ='P&L Input'!G26/'P&L Input'!G$14 -> 0.25469471
C25: Other Income | D25: ='P&L Input'!C28/'P&L Input'!C$14 -> 0.028046734 | E25: ='P&L Input'!D28/'P&L Input'!D$14 -> 0.02826692 | F25: ='P&L Input'!E28/'P&L Input'!E$14 -> 0.029536371 | G25: ='P&L Input'!F28/'P&L Input'!F$14 -> 0.028885287 | H25: ='P&L Input'!G28/'P&L Input'!G$14 -> 0.026790984
C26: Finance Costs | D26: ='P&L Input'!C30/'P&L Input'!C$14 -> 0.24456171 | E26: ='P&L Input'!D30/'P&L Input'!D$14 -> 0.22483742 | F26: ='P&L Input'!E30/'P&L Input'!E$14 -> 0.23019175 | G26: ='P&L Input'!F30/'P&L Input'!F$14 -> 0.22824899 | H26: ='P&L Input'!G30/'P&L Input'!G$14 -> 0.22790372
C28: Profit before Tax
C29: Taxes | D29: ='P&L Input'!C40/'P&L Input'!C$14 -> 0.064258972 | E29: ='P&L Input'!D40/'P&L Input'!D$14 -> 0.061645302 | F29: ='P&L Input'!E40/'P&L Input'!E$14 -> 0.061497276 | G29: ='P&L Input'!F40/'P&L Input'!F$14 -> 0.065177982 | H29: ='P&L Input'!G40/'P&L Input'!G$14 -> 0.057500601
B30: Net Profit | D30: ='P&L Input'!C42/'P&L Input'!C$14 -> 0.178689 | E30: ='P&L Input'!D42/'P&L Input'!D$14 -> 0.16129205 | F30: ='P&L Input'!E42/'P&L Input'!E$14 -> 0.16572695 | G30: ='P&L Input'!F42/'P&L Input'!F$14 -> 0.16057386 | H30: ='P&L Input'!G42/'P&L Input'!G$14 -> 0.16108476
B34: ASSETS
B36: Non-Current Assets
C37: PPE | D37: ='BS Input'!D12/'BS Input'!D$39 -> 0.11091318 | E37: ='BS Input'!E12/'BS Input'!E$39 -> 0.10607554 | F37: ='BS Input'!F12/'BS Input'!F$39 -> 0.08975866 | G37: ='BS Input'!G12/'BS Input'!G$39 -> 0.079098474 | H37: ='BS Input'!H12/'BS Input'!H$39 -> 0.081113312
C38: ROU Assets | D38: ='BS Input'!D13/'BS Input'!D$39 -> 0.040912754 | E38: ='BS Input'!E13/'BS Input'!E$39 -> 0.054698925 | F38: ='BS Input'!F13/'BS Input'!F$39 -> 0.04754234 | G38: ='BS Input'!G13/'BS Input'!G$39 -> 0.042383297 | H38: ='BS Input'!H13/'BS Input'!H$39 -> 0.039604532
C39: Capital WIP | D39: ='BS Input'!D14/'BS Input'!D$39 -> 0.0035288629 | E39: ='BS Input'!E14/'BS Input'!E$39 -> 0.002289057 | F39: ='BS Input'!F14/'BS Input'!F$39 -> 0.002126054 | G39: ='BS Input'!G14/'BS Input'!G$39 -> 0.0054666461 | H39: ='BS Input'!H14/'BS Input'!H$39 -> 0.0033725083
C40: Goodwill | D40: ='BS Input'!D15/'BS Input'!D$39 -> 0.052551215 | E40: ='BS Input'!E15/'BS Input'!E$39 -> 0.057607935 | F40: ='BS Input'!F15/'BS Input'!F$39 -> 0.052991713 | G40: ='BS Input'!G15/'BS Input'!G$39 -> 0.067869687 | H40: ='BS Input'!H15/'BS Input'!H$39 -> 0.077689511
C41: Other Intangible assets | D41: ='BS Input'!D16/'BS Input'!D$39 -> 0.014480214 | E41: ='BS Input'!E16/'BS Input'!E$39 -> 0.013901253 | F41: ='BS Input'!F16/'BS Input'!F$39 -> 0.010136851 | G41: ='BS Input'!G16/'BS Input'!G$39 -> 0.018575851 | H41: ='BS Input'!H16/'BS Input'!H$39 -> 0.018112806
C42: Financial Assets
C43: Investments | D43: ='BS Input'!D18/'BS Input'!D$39 -> 0.1157993 | E43: ='BS Input'!E18/'BS Input'!E$39 -> 0.099899854 | F43: ='BS Input'!F18/'BS Input'!F$39 -> 0.084955084 | G43: ='BS Input'!G18/'BS Input'!G$39 -> 0.074269827 | H43: ='BS Input'!H18/'BS Input'!H$39 -> 0.057255702
C44: Other financial assets | D44: ='BS Input'!D20/'BS Input'!D$39 -> 0.012384951 | E44: ='BS Input'!E20/'BS Input'!E$39 -> 0.022238825 | F44: ='BS Input'!F20/'BS Input'!F$39 -> 0.022530367 | G44: ='BS Input'!G20/'BS Input'!G$39 -> 0.023579109 | H44: ='BS Input'!H20/'BS Input'!H$39 -> 0.017798637
C45: Deferred Tax Assets(net) | D45: ='BS Input'!D21/'BS Input'!D$39 -> 0.010281206 | E45: ='BS Input'!E21/'BS Input'!E$39 -> 0.0098954028 | F45: ='BS Input'!F21/'BS Input'!F$39 -> 0.0032942952 | G45: ='BS Input'!G21/'BS Input'!G$39 -> 0.0074410858 | H45: ='BS Input'!H21/'BS Input'!H$39 -> 0.014515891
C46: Income tax assets (net) | D46: ='BS Input'!D22/'BS Input'!D$39 -> 0.051728379 | E46: ='BS Input'!E22/'BS Input'!E$39 -> 0.051289184 | F46: ='BS Input'!F22/'BS Input'!F$39 -> 0.022094998 | G46: ='BS Input'!G22/'BS Input'!G$39 -> 0.010892997 | H46: ='BS Input'!H22/'BS Input'!H$39 -> 0.0042701341
C47: Other non-current assets | D47: ='BS Input'!D23/'BS Input'!D$39 -> 0.017211689 | E47: ='BS Input'!E23/'BS Input'!E$39 -> 0.01842373 | F47: ='BS Input'!F23/'BS Input'!F$39 -> 0.015390309 | G47: ='BS Input'!G23/'BS Input'!G$39 -> 0.018219915 | H47: ='BS Input'!H23/'BS Input'!H$39 -> 0.022697109
B49: Current Assets
C50: Financial Assets
C51: Investments | D51: ='BS Input'!D29/'BS Input'!D$39 -> 0.056606014 | E51: ='BS Input'!E29/'BS Input'!E$39 -> 0.054913525 | F51: ='BS Input'!F29/'BS Input'!F$39 -> 0.093713266 | G51: ='BS Input'!G29/'BS Input'!G$39 -> 0.083826384 | H51: ='BS Input'!H29/'BS Input'!H$39 -> 0.083030385
C52: Trade Receivables | D52: ='BS Input'!D30/'BS Input'!D$39 -> 0.19254358 | E52: ='BS Input'!E30/'BS Input'!E$39 -> 0.20207287 | F52: ='BS Input'!F30/'BS Input'!F$39 -> 0.21908514 | G52: ='BS Input'!G30/'BS Input'!G$39 -> 0.20925032 | H52: ='BS Input'!H30/'BS Input'!H$39 -> 0.22590676
C53: Cash & Cash Equivalents | D53: ='BS Input'!D31/'BS Input'!D$39 -> 0.14821224 | E53: ='BS Input'!E31/'BS Input'!E$39 -> 0.0967524 | F53: ='BS Input'!F31/'BS Input'!F$39 -> 0.10728954 | G53: ='BS Input'!G31/'BS Input'!G$39 -> 0.16423443 | H53: ='BS Input'!H31/'BS Input'!H$39 -> 0.14234421
C54: Other financial assets | D54: ='BS Input'!D33/'BS Input'!D$39 -> 0.074029775 | E54: ='BS Input'!E33/'BS Input'!E$39 -> 0.092229923 | F54: ='BS Input'!F33/'BS Input'!F$39 -> 0.087690656 | G54: ='BS Input'!G33/'BS Input'!G$39 -> 0.092946415 | H54: ='BS Input'!H33/'BS Input'!H$39 -> 0.10188053
C55: Other current assets | D55: ='BS Input'!D35/'BS Input'!D$39 -> 0.095966408 | E55: ='BS Input'!E35/'BS Input'!E$39 -> 0.11505691 | F55: ='BS Input'!F35/'BS Input'!F$39 -> 0.092936857 | G55: ='BS Input'!G35/'BS Input'!G$39 -> 0.08018643 | H55: ='BS Input'!H35/'BS Input'!H$39 -> 0.097103875
B57: TOTAL | D57: ='BS Input'!D39/'BS Input'!D$39 -> 1 | E57: ='BS Input'!E39/'BS Input'!E$39 -> 1 | F57: ='BS Input'!F39/'BS Input'!F$39 -> 1 | G57: ='BS Input'!G39/'BS Input'!G$39 -> 1 | H57: ='BS Input'!H39/'BS Input'!H$39 -> 1
...

Sheet Revenue Buildup
B2: Infosys Limited
P6: (INR in Crores)
B7: Revenue Buildup
B8: Particulars | C8: 2022 | D8: =C8+1 -> 2023 | E8: =D8+1 -> 2024 | F8: =E8+1 -> 2025 | G8: =F8+1 -> 2026 | H8: =G8+1 -> 2027 | I8: =H8+1 -> 2028 | J8: =I8+1 -> 2029 | K8: =J8+1 -> 2030 | ... Q8: =P8+1 -> 2036
C9: Audited | D9: Audited | E9: Audited | F9: Audited | G9: Audited | H9: Estimated | I9: Projected | J9: Projected | K9: Projected | L9: Projected | M9: Projected | N9: Projected | O9: Projected | P9: Projected | Q9: Projected
B11: Sale of Service | C11: =C15-C12 -> 113536 | D11: =D15-D12 -> 137575 | E11: =E15-E12 -> 145285 | F11: =F15-F12 -> 155395 | G11: =G15-G12 -> 170122 | H11: =H15-H12 -> 184226.18 | I11: =I15-I12 -> 201780.73 | J11: =J15-J12 -> 219161.02 | ... Q11: =Q15-Q12 -> 309346.78
B12: Other Operating Revenues | C12: 8105 | D12: 9192 | E12: 8385 | F12: 7595 | G12: 8528 | H12: =H$13*H$28 -> 11547.509 | I12: =I$13*I$28 -> 12647.848 | J12: =J$13*J$28 -> 13737.265 | K12: =K$13*K$28 -> 14796.293 | L12: =L$13*L$28 -> 15804.64 | M12: =M$13*M$28 -> 16741.738 | N12: =N$13*N$28 -> 17587.332 | O12: =O$13*O$28 -> 18322.1 | ... Q12: =Q$13*Q$28 -> 19390.212
B13: (% on total Revenue) | C13: =C$12/C$11 -> 0.071387049 | D13: =D$12/D$11 -> 0.066814465 | E13: =E$12/E$11 -> 0.057714148 | F13: =F$12/F$11 -> 0.048875446 | G13: =G$12/G$11 -> 0.050128731 | H13: =AVERAGE(C13:G13) -> 0.058983968 | I13: =H13 -> 0.058983968 | J13: =I13 -> 0.058983968 | K13: =J13 -> 0.058983968 | L13: =K13 -> 0.058983968 | M13: =L13 -> 0.058983968 | N13: =M13 -> 0.058983968 | O13: =N13 -> 0.058983968 | P13: =O13 -> 0.058983968 | Q13: =P13 -> 0.058983968
B15: Revenue from Operations | C15: =C62 -> 121641 | D15: =D62 -> 146767 | E15: =E62 -> 153670 | F15: =F62 -> 162990 | G15: =G62 -> 178650 | H15: =H28 -> 195773.69 | I15: =I28 -> 214428.58 | J15: =J28 -> 232898.28 | K15: =K28 -> 250852.79 | L15: =L28 -> 267948.07 | M15: =M28 -> 283835.39 | N15: =N28 -> 298171.4 | O15: =O28 -> 310628.48 | ... Q15: =Q28 -> 328737
B16: Y-O-Y Growth | D16: =D15/C15-1 -> 0.20655864 | E16: =E15/D15-1 -> 0.047033734 | F16: =F15/E15-1 -> 0.060649444 | G16: =G15/F15-1 -> 0.096079514 | H16: =H15/G15-1 -> 0.095850477 | I16: =I15/H15-1 -> 0.095288044 | J16: =J15/I15-1 -> 0.086134516 | K16: =K15/J15-1 -> 0.077091624 | ... Q16: =Q15/P15-1 -> 0.024405003
B18: Other Income | C18: 2295 | D18: 2701 | E18: 4711 | F18: 3600 | G18: 4322 | H18: =H11*H19 -> 4452.554 | I18: =I11*I19 -> 4876.8291 | J18: =J11*J19 -> 5296.8924 | K18: =K11*K19 -> 5705.2385 | L18: =L11*L19 -> 6094.0427 | M18: =M11*M19 -> 6455.3741 | N18: =N11*N19 -> 6781.4232 | O18: =O11*O19 -> 7064.7393 | ... Q18: =Q11*Q19 -> 7476.5881
C19: =C18/C11 -> 0.020213853 | D19: =D18/D11 -> 0.019632927 | E19: =E18/E11 -> 0.032425921 | F19: =F18/F11 -> 0.023166769 | G19: =G18/G11 -> 0.025405297 | H19: =AVERAGE(C19:G19) -> 0.024168954 | I19: =H19 -> 0.024168954 | J19: =I19 -> 0.024168954 | K19: =J19 -> 0.024168954 | L19: =K19 -> 0.024168954 | M19: =L19 -> 0.024168954 | N19: =M19 -> 0.024168954 | O19: =N19 -> 0.024168954 | P19: =O19 -> 0.024168954 | Q19: =P19 -> 0.024168954
B22: Exceptional Items | C22: 0 | D22: 0 | E22: 0 | F22: 0 | G22: 1289 | H22: =H23*H11 -> 465.28872 | I22: =I23*I11 -> 509.62518 | J22: =J23*J11 -> 553.52149 | K22: =K23*K11 -> 596.19336 | L22: =L23*L11 -> 636.82313 | M22: =M23*M11 -> 674.582 | N22: =N23*N11 -> 708.6539 | O22: =O23*O11 -> 738.26024 | ... Q22: =Q23*Q11 -> 781.29814
C23: =C22/C11 -> 0 | D23: =D22/D11 -> 0 | E23: =E22/E11 -> 0 | F23: =F22/F11 -> 0 | G23: =G22/G11 -> 0.0075769154 | H23: =AVERAGE(E23:G23) -> 0.0025256385 | I23: =H23 -> 0.0025256385 | J23: =I23 -> 0.0025256385 | K23: =J23 -> 0.0025256385 | L23: =K23 -> 0.0025256385 | M23: =L23 -> 0.0025256385 | N23: =M23 -> 0.0025256385 | O23: =N23 -> 0.0025256385 | P23: =O23 -> 0.0025256385 | Q23: =P23 -> 0.0025256385
B24: Revenue by Geographies
B25: North America | C25: 0.617045 | D25: 0.61815 | E25: 0.60136 | F25: 0.579158 | G25: 0.560688 | H25: =$J$32*H$28 -> 109767.96 | I25: =$J$32*I$28 -> 120227.53 | J25: =$J$32*J$28 -> 130583.27 | K25: =$J$32*K$28 -> 140650.15 | L25: =$J$32*L$28 -> 150235.26 | M25: =$J$32*M$28 -> 159143.1 | N25: =$J$32*N$28 -> 167181.12 | O25: =$J$32*O$28 -> 174165.66 | ... Q25: =$J$32*Q$28 -> 184318.89
B26: Europe | C26: 0.247688 | D26: 0.256699 | E26: 0.27505 | F26: 0.298147 | G26: 0.321601 | H26: =$J$33*H$28 -> 62961.014 | I26: =$J$33*I$28 -> 68960.446 | J26: =$J$33*J$28 -> 74900.32 | K26: =$J$33*K$28 -> 80674.508 | L26: =$J$33*L$28 -> 86172.366 | M26: =$J$33*M$28 -> 91281.746 | N26: =$J$33*N$28 -> 95892.219 | O26: =$J$33*O$28 -> 99898.43 | ... Q26: =$J$33*Q$28 -> 105722.15
B27: Rest of the World* | C27: 0.135267 | D27: 0.125151 | E27: 0.12359 | F27: 0.122695 | G27: 0.117711 | H27: =$J$34*H$28 -> 26481.719 | I27: =$J$34*I$28 -> 29005.111 | J27: =$J$34*J$28 -> 31503.452 | K27: =$J$34*K$28 -> 33932.104 | L27: =$J$34*L$28 -> 36244.531 | M27: =$J$34*M$28 -> 38393.562 | N27: =$J$34*N$28 -> 40332.75 | O27: =$J$34*O$28 -> 42017.783 | ... Q27: =$J$34*Q$28 -> 44467.267
C28: =C15 -> 121641 | D28: =D15 -> 146767 | E28: =E15 -> 153670 | F28: =F15 -> 162990 | G28: =G15 -> 178650 | H28: =H62 -> 195773.69 | I28: =I62 -> 214428.58 | J28: =J62 -> 232898.28 | K28: =K62 -> 250852.79 | L28: =L62 -> 267948.07 | M28: =M62 -> 283835.39 | N28: =N62 -> 298171.4 | O28: =O62 -> 310628.48 | ... Q28: =Q62 -> 328737
B31: IT Sector Growth Projection | C31: United Kingdom | E31: North America | G31: AMEA | H31: Min Growth | J31: Revenue Segment By geography
B32: Digital & Application Engineering | C32: 0.0471 | E32: 0.0377 | G32: 0.0483 | H32: =MIN(C32:G32) -> 0.0377 | J32: =MIN(C25:G25) -> 0.560688
B33: Oracle Cloud & Enterprise Apps | C33: 0.1243 | E33: 0.153 | G33: 0.2094 | H33: =MIN(C33:G33) -> 0.1243 | J33: =MAX(C26:G26) -> 0.321601
B34: Digital Commerce & Experience | C34: 0.0483 | E34: 0.0338 | G34: 0.0584 | H34: =MIN(C34:G34) -> 0.0338 | J34: =MAX(C27:G27) -> 0.135267
B35: Data, Automation and AI | C35: 0.2633 | E35: 0.2688 | G35: 0.2661 | H35: =MIN(C35:G35) -> 0.2633
B37: Revenue by Geography | C37: 2022 | D37: 2023 | E37: 2024 | F37: 2025 | G37: 2026 | H37: 2027 | I37: 2028 | J37: 2029 | K37: 2030 | L37: 2031 | M37: 2032 | N37: 2033 | O37: 2034 | P37: 2035 | Q37: 2036
B38: North America | C38: 75058 | D38: 90724 | E38: 92411 | F38: 94397 | G38: 100167 | H38: =G38*(1+H$39) -> 106726.17 | I38: =H38*(1+I$39) -> 112697.6 | J38: =I38*(1+J$39) -> 117650.77 | K38: =J38*(1+K$39) -> 121409.83 | L38: =K38*(1+L$39) -> 123832.08 | M38: =L38*(1+M$39) -> 124816.66 | N38: =M38*(1+N$39) -> 124311.28 | O38: =N38*(1+O$39) -> 122316.21 | ... Q38: =P38*(1+Q$39) -> 114124.12
D39: =D38/C38-1 -> 0.20871859 | E39: =E38/D38-1 -> 0.018594859 | F39: =F38/E38-1 -> 0.021490948 | G39: =G38/F38-1 -> 0.061124824 | H39: {=CHOOSE(Assumptions!D17,'Revenue Buildup'!H40:Q40,'Revenue Buildup'!H41:Q41,'Revenue Buildup'!H42:Q42)} -> 0.065482306 | I39: 0.055950988 | J39: 0.043950988 | K39: 0.031950988 | L39: 0.019950988 | M39: 0.0079509884 | N39: -0.0040490116 | O39: -0.016049012 | P39: -0.028049012 | Q39: -0.040049012
H40: =H41+0.05 -> 0.11548231 | I40: =I41+MAX(0,(H40-H41)-Assumptions!$D$32) -> 0.095950988 | J40: =J41+MAX(0,(I40-I41)-Assumptions!$D$32) -> 0.073950988 | K40: =K41+MAX(0,(J40-J41)-Assumptions!$D$32) -> 0.051950988 | L40: =L41+MAX(0,(K40-K41)-Assumptions!$D$32) -> 0.029950988 | M40: =M41+MAX(0,(L40-L41)-Assumptions!$D$32) -> 0.0079509884 | N40: =N41+MAX(0,(M40-M41)-Assumptions!$D$32) -> -0.0040490116 | O40: =O41+MAX(0,(N40-N41)-Assumptions!$D$32) -> -0.016049012 | P40: =P41+MAX(0,(O40-O41)-Assumptions!$D$32) -> -0.028049012 | Q40: =Q41+MAX(0,(P40-P41)-Assumptions!$D$32) -> -0.040049012
H41: =AVERAGE(D39:G39)-0.012 -> 0.065482306 | I41: =(H41*(1+$H$32))-0.012 -> 0.055950988 | J41: =I41-0.012 -> 0.043950988 | K41: =J41-0.012 -> 0.031950988 | L41: =K41-0.012 -> 0.019950988 | M41: =L41-0.012 -> 0.0079509884 | N41: =M41-0.012 -> -0.0040490116 | O41: =N41-0.012 -> -0.016049012 | P41: =O41-0.012 -> -0.028049012 | Q41: =P41-0.012 -> -0.040049012
H42: =H41-0.05 -> 0.015482306 | I42: =I41-0.05 -> 0.0059509884 | J42: =J41-0.05 -> -0.0060490116 | K42: =K41-0.05 -> -0.018049012 | L42: =L41-0.05 -> -0.030049012 | M42: =M41-0.05 -> -0.042049012 | N42: =N41-0.05 -> -0.054049012 | O42: =O41-0.05 -> -0.066049012 | ... Q42: =Q41-0.05 -> -0.090049012
B44: Europe | C44: 30129 | D44: 37675 | E44: 42267 | F44: 48595 | G44: 57454 | H44: =G44*(1+H$45) -> 66881.606 | I44: =H44*(1+I$45) -> 78417.744 | J44: =I44*(1+J$45) -> 91002.692 | K44: =J44*(1+K$45) -> 104515.32 | L44: =K44*(1+L$45) -> 118780.19 | M44: =L44*(1+M$45) -> 133566.66 | N44: =M44*(1+N$45) -> 148591.03 | O44: =N44*(1+O$45) -> 163522.35 | ... Q44: =P44*(1+Q$45) -> 191605.66
D45: =D44/C44-1 -> 0.25045637 | E45: =E44/D44-1 -> 0.12188454 | F45: =F44/E44-1 -> 0.14971491 | G45: =G44/F44-1 -> 0.18230271 | H45: {=CHOOSE(Assumptions!D17,'Revenue Buildup'!H46:Q46,'Revenue Buildup'!H47:Q47,'Revenue Buildup'!H48:Q48)} -> 0.16408963 | I45: 0.17248597 | J45: 0.16048597 | K45: 0.14848597 | L45: 0.13648597 | M45: 0.12448597 | N45: 0.11248597 | O45: 0.10048597 | P45: 0.088485972 | Q45: 0.076485972
H46: =H47+0.05 -> 0.21408963 | I46: =I47+MAX(0,(H46-H47)-Assumptions!$D$32) -> 0.21248597 | J46: =J47+MAX(0,(I46-I47)-Assumptions!$D$32) -> 0.19048597 | K46: =K47+MAX(0,(J46-J47)-Assumptions!$D$32) -> 0.16848597 | L46: =L47+MAX(0,(K46-K47)-Assumptions!$D$32) -> 0.14648597 | M46: =M47+MAX(0,(L46-L47)-Assumptions!$D$32) -> 0.12448597 | N46: =N47+MAX(0,(M46-M47)-Assumptions!$D$32) -> 0.11248597 | O46: =O47+MAX(0,(N46-N47)-Assumptions!$D$32) -> 0.10048597 | P46: =P47+MAX(0,(O46-O47)-Assumptions!$D$32) -> 0.088485972 | Q46: =Q47+MAX(0,(P46-P47)-Assumptions!$D$32) -> 0.076485972
H47: =AVERAGE(D45:G45)-0.012 -> 0.16408963 | I47: =(H47*(1+$H$33))-0.012 -> 0.17248597 | J47: =I47-0.012 -> 0.16048597 | K47: =J47-0.012 -> 0.14848597 | L47: =K47-0.012 -> 0.13648597 | M47: =L47-0.012 -> 0.12448597 | N47: =M47-0.012 -> 0.11248597 | O47: =N47-0.012 -> 0.10048597 | P47: =O47-0.012 -> 0.088485972 | Q47: =P47-0.012 -> 0.076485972
H48: =H47-0.05 -> 0.11408963 | I48: =I47-0.05 -> 0.12248597 | J48: =J47-0.05 -> 0.11048597 | K48: =K47-0.05 -> 0.098485972 | L48: =L47-0.05 -> 0.086485972 | M48: =M47-0.05 -> 0.074485972 | N48: =N47-0.05 -> 0.062485972 | O48: =O47-0.05 -> 0.050485972 | ... Q48: =Q47-0.05 -> 0.026485972
B50: India | C50: 3585 | D50: 3861 | E50: 3881 | F50: 5014 | G50: 5102 | H50: =G50*(1+H$51) -> 5540.3299 | I50: =H50*(1+I$51) -> 5965.9226 | J50: =I50*(1+J$51) -> 6352.6171 | K50: =J50*(1+K$51) -> 6688.1446 | L50: =K50*(1+L$51) -> 6961.1361 | M50: =L50*(1+M$51) -> 7161.7366 | N50: =M50*(1+N$51) -> 7282.1771 | O50: =N50*(1+O$51) -> 7317.2569 | ... Q50: =P50*(1+Q$51) -> 7125.3415
D51: =D50/C50-1 -> 0.076987448 | E51: =E50/D50-1 -> 0.0051800052 | F51: =F50/E50-1 -> 0.29193507 | G51: =G50/F50-1 -> 0.017550858 | H51: {=CHOOSE(Assumptions!D17,'Revenue Buildup'!H52:Q52,'Revenue Buildup'!H53:Q53,'Revenue Buildup'!H54:Q54)} -> 0.085913345 | I51: 0.076817216 | J51: 0.064817216 | K51: 0.052817216 | L51: 0.040817216 | M51: 0.028817216 | N51: 0.016817216 | O51: 0.0048172157 | P51: -0.0071827843 | Q51: -0.019182784
H52: =H53+0.05 -> 0.13591334 | I52: =I53+MAX(0,(H52-H53)-Assumptions!$D$32) -> 0.11681722 | J52: =J53+MAX(0,(I52-I53)-Assumptions!$D$32) -> 0.094817216 | K52: =K53+MAX(0,(J52-J53)-Assumptions!$D$32) -> 0.072817216 | L52: =L53+MAX(0,(K52-K53)-Assumptions!$D$32) -> 0.050817216 | M52: =M53+MAX(0,(L52-L53)-Assumptions!$D$32) -> 0.028817216 | N52: =N53+MAX(0,(M52-M53)-Assumptions!$D$32) -> 0.016817216 | O52: =O53+MAX(0,(N52-N53)-Assumptions!$D$32) -> 0.0048172157 | P52: =P53+MAX(0,(O52-O53)-Assumptions!$D$32) -> -0.0071827843 | Q52: =Q53+MAX(0,(P52-P53)-Assumptions!$D$32) -> -0.019182784
H53: =AVERAGE(D51:G51)-0.012 -> 0.085913345 | I53: =(H53*(1+$H$34))-0.012 -> 0.076817216 | J53: =I53-0.012 -> 0.064817216 | K53: =J53-0.012 -> 0.052817216 | L53: =K53-0.012 -> 0.040817216 | M53: =L53-0.012 -> 0.028817216 | N53: =M53-0.012 -> 0.016817216 | O53: =N53-0.012 -> 0.0048172157 | P53: =O53-0.012 -> -0.0071827843 | Q53: =P53-0.012 -> -0.019182784
H54: =H53-0.05 -> 0.035913345 | I54: =I53-0.05 -> 0.026817216 | J54: =J53-0.05 -> 0.014817216 | K54: =K53-0.05 -> 0.0028172157 | L54: =L53-0.05 -> -0.0091827843 | M54: =M53-0.05 -> -0.021182784 | N54: =N53-0.05 -> -0.033182784 | O54: =O53-0.05 -> -0.045182784 | ... Q54: =Q53-0.05 -> -0.069182784
...

Sheet Cost Buildup
B2: Infosys Limited
P6: (INR in Crores)
B7: Cost Build-up
B8: Particulars | C8: ='Revenue Buildup'!C8 -> 2022 | D8: ='Revenue Buildup'!D8 -> 2023 | E8: ='Revenue Buildup'!E8 -> 2024 | F8: ='Revenue Buildup'!F8 -> 2025 | G8: ='Revenue Buildup'!G8 -> 2026 | H8: ='Revenue Buildup'!H8 -> 2027 | I8: ='Revenue Buildup'!I8 -> 2028 | J8: ='Revenue Buildup'!J8 -> 2029 | ... Q8: ='Revenue Buildup'!Q8 -> 2036
C9: Audited | D9: Audited | E9: Audited | F9: Audited | G9: Audited | H9: Estimated | I9: Projected | J9: Projected | K9: Projected | L9: Projected | M9: Projected | N9: Projected | O9: Projected | P9: Projected | Q9: Projected
B11: ='Revenue Buildup'!B15 -> Revenue from Operations | C11: ='Revenue Buildup'!C15 -> 121641 | D11: ='Revenue Buildup'!D15 -> 146767 | E11: ='Revenue Buildup'!E15 -> 153670 | F11: ='Revenue Buildup'!F15 -> 162990 | G11: ='Revenue Buildup'!G15 -> 178650 | H11: ='Revenue Buildup'!H15 -> 195773.69 | I11: ='Revenue Buildup'!I15 -> 214428.58 | ... Q11: ='Revenue Buildup'!Q15 -> 328737
B13: Employee Benefit Expenses | C13: ='P&L Input'!C17 -> 63986 | D13: ='P&L Input'!D17 -> 78359 | E13: ='P&L Input'!E17 -> 82620 | F13: ='P&L Input'!F17 -> 85950 | G13: ='P&L Input'!G17 -> 95094 | H13: =H11*H14 -> 104041.76 | I13: =I11*I14 -> 113955.7 | J13: =J11*J14 -> 123771.22 | K13: =K11*K14 -> 133312.94 | L13: =L11*L14 -> 142398.04 | M13: =M11*M14 -> 150841.18 | N13: =N11*N14 -> 158459.89 | O13: =O11*O14 -> 165080.07 | ... Q13: =Q11*Q14 -> 174703.64
C14: =C13/C$11 -> 0.5260233 | D14: =D13/D$11 -> 0.53390067 | E14: =E13/E$11 -> 0.5376456 | F14: =F13/F$11 -> 0.52733297 | G14: =G13/G$11 -> 0.53229219 | H14: =AVERAGE(C14:G14) -> 0.53143895 | I14: =H14 -> 0.53143895 | J14: =I14 -> 0.53143895 | K14: =J14 -> 0.53143895 | L14: =K14 -> 0.53143895 | M14: =L14 -> 0.53143895 | N14: =M14 -> 0.53143895 | O14: =N14 -> 0.53143895 | P14: =O14 -> 0.53143895 | Q14: =P14 -> 0.53143895
B16: ='P&L Input'!B18 -> Cost of technical sub-contractors | C16: ='P&L Input'!C18 -> 12606 | D16: ='P&L Input'!D18 -> 14062 | E16: ='P&L Input'!E18 -> 12232 | F16: ='P&L Input'!F18 -> 12937 | G16: ='P&L Input'!G18 -> 15421 | H16: =H11*H17 -> 17413.532 | I16: =I11*I17 -> 19072.834 | J16: =J11*J17 -> 20715.663 | K16: =K11*K17 -> 22312.667 | L16: =L11*L17 -> 23833.245 | M16: =M11*M17 -> 25246.379 | N16: =N11*N17 -> 26521.527 | O16: =O11*O17 -> 27629.551 | ... Q16: =Q11*Q17 -> 29240.254
C17: =C16/C$11 -> 0.10363282 | D17: =D16/D$11 -> 0.095811729 | E17: =E16/E$11 -> 0.079599141 | F17: =F16/F$11 -> 0.079372968 | G17: =G16/G$11 -> 0.086319619 | H17: =AVERAGE(C17:G17) -> 0.088947256 | I17: =H17 -> 0.088947256 | J17: =I17 -> 0.088947256 | K17: =J17 -> 0.088947256 | L17: =K17 -> 0.088947256 | M17: =L17 -> 0.088947256 | N17: =M17 -> 0.088947256 | O17: =N17 -> 0.088947256 | P17: =O17 -> 0.088947256 | Q17: =P17 -> 0.088947256
B19: ='P&L Input'!B19 -> Travel expenses | C19: ='P&L Input'!C19 -> 827 | D19: ='P&L Input'!D19 -> 1525 | E19: ='P&L Input'!E19 -> 1759 | F19: ='P&L Input'!F19 -> 1894 | G19: ='P&L Input'!G19 -> 2097 | H19: =H11*H20 -> 2035.8232 | I19: =I11*I20 -> 2229.8128 | J19: =J11*J20 -> 2421.8766 | K19: =K11*K20 -> 2608.583 | L19: =L11*L20 -> 2786.3544 | M19: =M11*M20 -> 2951.5645 | N19: =N11*N20 -> 3100.6426 | O19: =O11*O20 -> 3230.1821 | ... Q19: =Q11*Q20 -> 3418.49
C20: =C19/C$11 -> 0.0067986945 | D20: =D19/D$11 -> 0.010390619 | E20: =E19/E$11 -> 0.011446606 | F20: =F19/F$11 -> 0.011620345 | G20: =G19/G$11 -> 0.011738035 | H20: =AVERAGE(C20:G20) -> 0.01039886 | I20: =H20 -> 0.01039886 | J20: =I20 -> 0.01039886 | K20: =J20 -> 0.01039886 | L20: =K20 -> 0.01039886 | M20: =L20 -> 0.01039886 | N20: =M20 -> 0.01039886 | O20: =N20 -> 0.01039886 | P20: =O20 -> 0.01039886 | Q20: =P20 -> 0.01039886
B22: ='P&L Input'!B20 -> Cost of software packages and others | C22: ='P&L Input'!C20 -> 6811 | D22: ='P&L Input'!D20 -> 10902 | E22: ='P&L Input'!E20 -> 13515 | F22: ='P&L Input'!F20 -> 15911 | G22: ='P&L Input'!G20 -> 15722 | H22: =H11*H23 -> 15812.476 | I22: =I11*I23 -> 17319.216 | J22: =J11*J23 -> 18810.999 | K22: =K11*K23 -> 20261.169 | L22: =L11*L23 -> 21641.94 | M22: =M11*M23 -> 22925.146 | N22: =N11*N23 -> 24083.053 | O22: =O11*O23 -> 25089.202 | ... Q22: =Q11*Q23 -> 26551.811
C23: =C22/C$11 -> 0.055992634 | D23: =D22/D$11 -> 0.074281003 | E23: =E22/E$11 -> 0.087948201 | F23: =F22/F$11 -> 0.097619486 | G23: =G22/G$11 -> 0.088004478 | H23: =AVERAGE(C23:G23) -> 0.08076916 | I23: =H23 -> 0.08076916 | J23: =I23 -> 0.08076916 | K23: =J23 -> 0.08076916 | L23: =K23 -> 0.08076916 | M23: =L23 -> 0.08076916 | N23: =M23 -> 0.08076916 | O23: =N23 -> 0.08076916 | P23: =O23 -> 0.08076916 | Q23: =P23 -> 0.08076916
B25: ='P&L Input'!B21 -> Communication expenses | C25: ='P&L Input'!C21 -> 611 | D25: ='P&L Input'!D21 -> 713 | E25: ='P&L Input'!E21 -> 677 | F25: ='P&L Input'!F21 -> 620 | G25: ='P&L Input'!G21 -> 603 | H25: =H26*H11 -> 840.48742 | I25: =I26*I11 -> 920.57583 | J25: =J26*J11 -> 999.86918 | K25: =K26*K11 -> 1076.9507 | L25: =L26*L11 -> 1150.3434 | M25: =M26*M11 -> 1218.5503 | N25: =N26*N11 -> 1280.097 | O25: =O26*O11 -> 1333.5772 | ... Q25: =Q26*Q11 -> 1411.32
C26: =C25/C$11 -> 0.0050229775 | D26: =D25/D$11 -> 0.0048580403 | E26: =E25/E$11 -> 0.0044055443 | F26: =F25/F$11 -> 0.0038039144 | G26: =G25/G$11 -> 0.0033753149 | H26: =AVERAGE(C26:G26) -> 0.0042931583 | I26: =H26 -> 0.0042931583 | J26: =I26 -> 0.0042931583 | K26: =J26 -> 0.0042931583 | L26: =K26 -> 0.0042931583 | M26: =L26 -> 0.0042931583 | N26: =M26 -> 0.0042931583 | O26: =N26 -> 0.0042931583 | P26: =O26 -> 0.0042931583 | Q26: =P26 -> 0.0042931583
B28: ='P&L Input'!B22 -> Consultancy and professional charges | C28: ='P&L Input'!C22 -> 1885 | D28: ='P&L Input'!D22 -> 1684 | E28: ='P&L Input'!E22 -> 1726 | F28: ='P&L Input'!F22 -> 1655 | G28: ='P&L Input'!G22 -> 2090 | H28: =H11*H29 -> 2351.4416 | I28: =I11*I29 -> 2575.5059 | J28: =J11*J29 -> 2797.3459 | K28: =K11*K29 -> 3012.9978 | L28: =L11*L29 -> 3218.3295 | M28: =M11*M29 -> 3409.1525 | N28: =N11*N29 -> 3581.3425 | O28: =O11*O29 -> 3730.9648 | ... Q28: =Q11*Q29 -> 3948.4666
C29: =C28/C$11 -> 0.01549642 | D29: =D28/D$11 -> 0.011473969 | E29: =E28/E$11 -> 0.01123186 | F29: =F28/F$11 -> 0.010153997 | G29: =G28/G$11 -> 0.011698853 | H29: =AVERAGE(C29:G29) -> 0.01201102 | I29: =H29 -> 0.01201102 | J29: =I29 -> 0.01201102 | K29: =J29 -> 0.01201102 | L29: =K29 -> 0.01201102 | M29: =L29 -> 0.01201102 | N29: =M29 -> 0.01201102 | O29: =N29 -> 0.01201102 | P29: =O29 -> 0.01201102 | Q29: =P29 -> 0.01201102
B31: Other Expenses | C31: ='P&L Input'!C23 -> 3424 | D31: ='P&L Input'!D23 -> 4392 | E31: ='P&L Input'!E23 -> 4716 | F31: ='P&L Input'!F23 -> 4787 | G31: ='P&L Input'!G23 -> 5343 | H31: =H11*H32 -> 5796.47 | I31: =I11*I32 -> 6348.8042 | J31: =J11*J32 -> 6895.6554 | K31: =K11*K32 -> 7427.2527 | L31: =L11*L32 -> 7933.4099 | M31: =M11*M32 -> 8403.802 | N31: =N11*N32 -> 8828.2627 | O31: =O11*O32 -> 9197.0922 | ... Q31: =Q11*Q32 -> 9733.2494
C32: =C31/C$11 -> 0.028148404 | D32: =D31/D$11 -> 0.029924983 | E32: =E31/E$11 -> 0.030689139 | F32: =F31/F$11 -> 0.0293699 | G32: =G31/G$11 -> 0.029907641 | H32: =AVERAGE(C32:G32) -> 0.029608013 | I32: =H32 -> 0.029608013 | J32: =I32 -> 0.029608013 | K32: =J32 -> 0.029608013 | L32: =K32 -> 0.029608013 | M32: =L32 -> 0.029608013 | N32: =M32 -> 0.029608013 | O32: =N32 -> 0.029608013 | P32: =O32 -> 0.029608013 | Q32: =P32 -> 0.029608013
B34: Finance Costs | C34: ='P&L Input'!C32 -> 200 | D34: ='P&L Input'!D32 -> 284 | E34: ='P&L Input'!E32 -> 470 | F34: ='P&L Input'!F32 -> 416 | G34: ='P&L Input'!G32 -> 416 | H34: =H11*H35 -> 8727.0051 | I34: =I11*I35 -> 9558.5843 | J34: =J11*J35 -> 10381.908 | K34: =K11*K35 -> 11182.267 | L34: =L11*L35 -> 11944.323 | M34: =M11*M35 -> 12652.532 | N34: =N11*N35 -> 13291.588 | O34: =O11*O35 -> 13846.888 | ... Q34: =Q11*Q35 -> 14654.111
B35: (as % of period-end Lease Liabilities) | C35: =C34/('BS Input'!D52+'BS Input'!D61) -> 0.036536354 | D35: =D34/('BS Input'!E52+'BS Input'!E61) -> 0.03422099 | E35: =E34/('BS Input'!F52+'BS Input'!F61) -> 0.056226821 | F35: =F34/('BS Input'!G52+'BS Input'!G61) -> 0.050565212 | G35: =G34/('BS Input'!H52+'BS Input'!H61) -> 0.045335658 | H35: =AVERAGE(C35:G35) -> 0.044577007 | I35: =H35 -> 0.044577007 | J35: =I35 -> 0.044577007 | K35: =J35 -> 0.044577007 | L35: =K35 -> 0.044577007 | M35: =L35 -> 0.044577007 | N35: =M35 -> 0.044577007 | O35: =N35 -> 0.044577007 | P35: =O35 -> 0.044577007 | Q35: =P35 -> 0.044577007
B37: Effective Tax rate | C37: ='P&L Input'!C40/'P&L Input'!C38 -> 0.26449684 | D37: ='P&L Input'!D40/'P&L Input'!D38 -> 0.27651401 | E37: ='P&L Input'!E40/'P&L Input'!E38 -> 0.27064577 | F37: ='P&L Input'!F40/'P&L Input'!F38 -> 0.28871517 | G37: ='P&L Input'!G40/'P&L Input'!G38 -> 0.26305788 | H37: =G37+0.3% -> 0.26605788 | I37: =H37+0.3% -> 0.26905788 | J37: =I37+0.3% -> 0.27205788 | K37: =J37+0.3% -> 0.27505788 | L37: =K37+0.3% -> 0.27805788 | M37: =L37+0.3% -> 0.28105788 | N37: =M37+0.3% -> 0.28405788 | O37: =N37+0.3% -> 0.28705788 | ... Q37: =P37+0.3% -> 0.29305788

Sheet FAS
B2: Infosys Limited
P6: (INR in Crores)
B7: Fixed Assets Schedule
B8: Particulars | C8: ='Cost Buildup'!C8 -> 2022 | D8: ='Cost Buildup'!D8 -> 2023 | E8: ='Cost Buildup'!E8 -> 2024 | F8: ='Cost Buildup'!F8 -> 2025 | G8: ='Cost Buildup'!G8 -> 2026 | H8: ='Cost Buildup'!H8 -> 2027 | I8: ='Cost Buildup'!I8 -> 2028 | J8: ='Cost Buildup'!J8 -> 2029 | ... Q8: ='Cost Buildup'!Q8 -> 2036
C9: Audited | D9: Audited | E9: Audited | F9: Audited | G9: Audited | H9: Estimated | I9: Projected | J9: Projected | K9: Projected | L9: Projected | M9: Projected | N9: Projected | O9: Projected | P9: Projected | Q9: Projected
B10: PPE Assets
B11: Buildings
B12: Opening Gross Block | C12: 10565 | D12: =C15 -> 11224 | E12: =D15 -> 11562 | F12: =E15 -> 11770 | G12: =F15 -> 11721 | H12: =G15 -> 12574 | I12: =H15 -> 13302 | J12: =I15 -> 14030 | K12: =J15 -> 14758 | ... Q12: =P15 -> 19391.574
B13: Additions | C13: 598 | D13: 337 | E13: 245 | F13: -69 | G13: 700 | H13: =G13*1.04 -> 728 | I13: =H13 -> 728 | J13: =I13 -> 728 | K13: =J13*1.04 -> 757.12 | L13: =K13 -> 757.12 | M13: =L13 -> 757.12 | N13: =M13*1.04 -> 787.4048 | O13: =N13 -> 787.4048 | P13: =O13 -> 787.4048 | Q13: =P13*1.04 -> 818.90099
B14: Forex fluctuations | C14: 61 | D14: 1 | E14: -37 | F14: 20 | G14: 153
B15: Closing Gross Block | C15: =SUM(C12:C14) -> 11224 | D15: =SUM(D12:D14) -> 11562 | E15: =SUM(E12:E14) -> 11770 | F15: =SUM(F12:F14) -> 11721 | G15: =SUM(G12:G14) -> 12574 | H15: =SUM(H12:H14) -> 13302 | I15: =SUM(I12:I14) -> 14030 | J15: =SUM(J12:J14) -> 14758 | ... Q15: =SUM(Q12:Q14) -> 20210.475
B16: Accumulated Depreciation | C16: 3675 | D16: =SUM(C16:C18) -> 4100 | E16: =SUM(D16:D18) -> 4535 | F16: =SUM(E16:E18) -> 4921 | G16: =SUM(F16:F18) -> 5358 | H16: =SUM(G16:G18) -> 5856 | I16: =SUM(H16:H18) -> 6320.88 | J16: =SUM(I16:I18) -> 6785.76 | K16: =SUM(J16:J18) -> 7250.64 | ... Q16: =SUM(P16:P18) -> 10209.508
B17: Depreciation for year | C17: 417 | D17: 434 | E17: 395 | F17: 431 | G17: 447 | H17: =G17*1.04 -> 464.88 | I17: =H17 -> 464.88 | J17: =I17 -> 464.88 | K17: =J17*1.04 -> 483.4752 | L17: =K17 -> 483.4752 | M17: =L17 -> 483.4752 | N17: =M17*1.04 -> 502.81421 | O17: =N17 -> 502.81421 | P17: =O17 -> 502.81421 | Q17: =P17*1.04 -> 522.92678
B18: Forex fluctuations | C18: 8 | D18: 1 | E18: -9 | F18: 6 | G18: 51
B19: Net Block | C19: =C15-SUM(C16:C18) -> 7124 | D19: =D15-SUM(D16:D18) -> 7027 | E19: =E15-SUM(E16:E18) -> 6849 | F19: =F15-SUM(F16:F18) -> 6363 | G19: =G15-SUM(G16:G18) -> 6718 | H19: =H15-SUM(H16:H18) -> 6981.12 | I19: =I15-SUM(I16:I18) -> 7244.24 | J19: =J15-SUM(J16:J18) -> 7507.36 | ... Q19: =Q15-SUM(Q16:Q18) -> 9478.0404
B21: Computers
B22: Opening Gross Block | C22: 7639 | D22: =C27 -> 8527 | E22: =D27 -> 8519 | F22: =E27 -> 8611 | G22: =F27 -> 9306 | H22: =G27 -> 9607 | I22: =H27 -> 9916.92 | J22: =I27 -> 10226.84 | K22: =J27 -> 10536.76 | ... Q22: =P27 -> 12509.339
B23: Acquired through BC | C23: 0 | D23: 6 | E23: 0 | F23: 6 | G23: 3
B24: Additions | C24: 1542 | D24: 1510 | E24: 931 | F24: 1317 | G24: 1524 | H24: =G24*1.04 -> 1584.96 | I24: =H24 -> 1584.96 | J24: =I24 -> 1584.96 | K24: =J24*1.04 -> 1648.3584 | L24: =K24 -> 1648.3584 | M24: =L24 -> 1648.3584 | N24: =M24*1.04 -> 1714.2927 | O24: =N24 -> 1714.2927 | P24: =O24 -> 1714.2927 | Q24: =P24*1.04 -> 1782.8644
B25: Forex fluctuations | C25: 18 | D25: 39 | E25: 7 | F25: 5 | G25: 99 | H25: =G25*1.04 -> 102.96 | I25: =H25 -> 102.96 | J25: =I25 -> 102.96 | K25: =J25*1.04 -> 107.0784 | L25: =K25 -> 107.0784 | M25: =L25 -> 107.0784 | N25: =M25*1.04 -> 111.36154 | O25: =N25 -> 111.36154 | P25: =O25 -> 111.36154 | Q25: =P25*1.04 -> 115.816
B26: Disposal | C26: -672 | D26: -1563 | E26: -846 | F26: -633 | G26: -1325 | H26: =G26*1.04 -> -1378 | I26: =H26 -> -1378 | J26: =I26 -> -1378 | K26: =J26*1.04 -> -1433.12 | L26: =K26 -> -1433.12 | M26: =L26 -> -1433.12 | N26: =M26*1.04 -> -1490.4448 | O26: =N26 -> -1490.4448 | P26: =O26 -> -1490.4448 | Q26: =P26*1.04 -> -1550.0626
B27: Closing Gross Block | C27: =SUM(C22:C26) -> 8527 | D27: =SUM(D22:D26) -> 8519 | E27: =SUM(E22:E26) -> 8611 | F27: =SUM(F22:F26) -> 9306 | G27: =SUM(G22:G26) -> 9607 | H27: =SUM(H22:H26) -> 9916.92 | I27: =SUM(I22:I26) -> 10226.84 | J27: =SUM(J22:J26) -> 10536.76 | ... Q27: =SUM(Q22:Q26) -> 12857.957
B28: Accumulated Depreciation | C28: 5636 | D28: =SUM(C28:C31) -> 6034 | E28: =SUM(D28:D31) -> 5826 | F28: =SUM(E28:E31) -> 6380 | G28: =SUM(F28:F31) -> 7013 | H28: =SUM(G28:G31) -> 6850 | I28: =SUM(H28:H31) -> 6680.48 | J28: =SUM(I28:I31) -> 6510.96 | K28: =SUM(J28:J31) -> 6341.44 | ... Q28: =SUM(P28:P31) -> 5262.4791
B29: Depreciation for year | C29: 1055 | D29: 1322 | E29: 1387 | F29: 1249 | G29: 1079 | H29: =G29*1.04 -> 1122.16 | I29: =H29 -> 1122.16 | J29: =I29 -> 1122.16 | K29: =J29*1.04 -> 1167.0464 | L29: =K29 -> 1167.0464 | M29: =L29 -> 1167.0464 | N29: =M29*1.04 -> 1213.7283 | O29: =N29 -> 1213.7283 | P29: =O29 -> 1213.7283 | Q29: =P29*1.04 -> 1262.2774
B30: Forex fluctuations | C30: 14 | D30: 26 | E30: 3 | F30: 0 | G30: 60 | H30: =G30*1.04 -> 62.4 | I30: =H30 -> 62.4 | J30: =I30 -> 62.4 | K30: =J30*1.04 -> 64.896 | L30: =K30 -> 64.896 | M30: =L30 -> 64.896 | N30: =M30*1.04 -> 67.49184 | O30: =N30 -> 67.49184 | P30: =O30 -> 67.49184 | Q30: =P30*1.04 -> 70.191514
B31: Disposal | C31: -671 | D31: -1556 | E31: -836 | F31: -616 | G31: -1302 | H31: =G31*1.04 -> -1354.08 | I31: =H31 -> -1354.08 | J31: =I31 -> -1354.08 | K31: =J31*1.04 -> -1408.2432 | L31: =K31 -> -1408.2432 | M31: =L31 -> -1408.2432 | N31: =M31*1.04 -> -1464.5729 | O31: =N31 -> -1464.5729 | P31: =O31 -> -1464.5729 | Q31: =P31*1.04 -> -1523.1558
B32: Net Block | C32: =C27-SUM(C28:C31) -> 2493 | D32: =D27-SUM(D28:D31) -> 2693 | E32: =E27-SUM(E28:E31) -> 2231 | F32: =F27-SUM(F28:F31) -> 2293 | G32: =G27-SUM(G28:G31) -> 2757 | H32: =H27-SUM(H28:H31) -> 3236.44 | I32: =I27-SUM(I28:I31) -> 3715.88 | J32: =J27-SUM(J28:J31) -> 4195.32 | ... Q32: =Q27-SUM(Q28:Q31) -> 7786.1645
B34: Plants & Equipment
B35: Opening Gross Block | C35: 3296 | D35: =C39 -> 3210 | E35: =D39 -> 3302 | F35: =E39 -> 3428 | G35: =F39 -> 3461 | H35: =G39 -> 3714 | I35: =H39 -> 3977.12 | J35: =I39 -> 4240.24 | K35: =J39 -> 4503.36 | ... Q35: =P39 -> 6178.0662
B36: Additions | C36: 256 | D36: 273 | E36: 193 | F36: 63 | G36: 270 | H36: =G36*1.04 -> 280.8 | I36: =H36 -> 280.8 | J36: =I36 -> 280.8 | K36: =J36*1.04 -> 292.032 | L36: =K36 -> 292.032 | M36: =L36 -> 292.032 | N36: =M36*1.04 -> 303.71328 | O36: =N36 -> 303.71328 | P36: =O36 -> 303.71328 | Q36: =P36*1.04 -> 315.86181
B37: Forex fluctuations | C37: 7 | D37: 1 | E37: -3 | F37: 1 | G37: 14 | H37: =G37*1.04 -> 14.56 | I37: =H37 -> 14.56 | J37: =I37 -> 14.56 | K37: =J37*1.04 -> 15.1424 | L37: =K37 -> 15.1424 | M37: =L37 -> 15.1424 | N37: =M37*1.04 -> 15.748096 | O37: =N37 -> 15.748096 | P37: =O37 -> 15.748096 | Q37: =P37*1.04 -> 16.37802
B38: Disposal | C38: -349 | D38: -182 | E38: -64 | F38: -31 | G38: -31 | H38: =G38*1.04 -> -32.24 | I38: =H38 -> -32.24 | J38: =I38 -> -32.24 | K38: =J38*1.04 -> -33.5296 | L38: =K38 -> -33.5296 | M38: =L38 -> -33.5296 | N38: =M38*1.04 -> -34.870784 | O38: =N38 -> -34.870784 | P38: =O38 -> -34.870784 | Q38: =P38*1.04 -> -36.265615
B39: Closing Gross Block | C39: =SUM(C35:C38) -> 3210 | D39: =SUM(D35:D38) -> 3302 | E39: =SUM(E35:E38) -> 3428 | F39: =SUM(F35:F38) -> 3461 | G39: =SUM(G35:G38) -> 3714 | H39: =SUM(H35:H38) -> 3977.12 | I39: =SUM(I35:I38) -> 4240.24 | J39: =SUM(J35:J38) -> 4503.36 | ... Q39: =SUM(Q35:Q38) -> 6474.0404
B40: Accumulated Depreciation | C40: 2425 | D40: =SUM(C40:C43) -> 2344 | E40: =SUM(D40:D43) -> 2437 | F40: =SUM(E40:E43) -> 2630 | G40: =SUM(F40:F43) -> 2813 | H40: =SUM(G40:G43) -> 2985 | I40: =SUM(H40:H43) -> 3163.88 | J40: =SUM(I40:I43) -> 3342.76 | K40: =SUM(J40:J43) -> 3521.64 | ... Q40: =SUM(P40:P43) -> 4660.1754
B41: Depreciation for year | C41: 245 | D41: 273 | E41: 259 | F41: 203 | G41: 188 | H41: =G41*1.04 -> 195.52 | I41: =H41 -> 195.52 | J41: =I41 -> 195.52 | K41: =J41*1.04 -> 203.3408 | L41: =K41 -> 203.3408 | M41: =L41 -> 203.3408 | N41: =M41*1.04 -> 211.47443 | O41: =N41 -> 211.47443 | P41: =O41 -> 211.47443 | Q41: =P41*1.04 -> 219.93341
B42: Forex fluctuations | C42: 4 | D42: 1 | E42: -2 | F42: 1 | G42: 14 | H42: =G42*1.04 -> 14.56 | I42: =H42 -> 14.56 | J42: =I42 -> 14.56 | K42: =J42*1.04 -> 15.1424 | L42: =K42 -> 15.1424 | M42: =L42 -> 15.1424 | N42: =M42*1.04 -> 15.748096 | O42: =N42 -> 15.748096 | P42: =O42 -> 15.748096 | Q42: =P42*1.04 -> 16.37802
B43: Disposal | C43: -330 | D43: -181 | E43: -64 | F43: -21 | G43: -30 | H43: =G43*1.04 -> -31.2 | I43: =H43 -> -31.2 | J43: =I43 -> -31.2 | K43: =J43*1.04 -> -32.448 | L43: =K43 -> -32.448 | M43: =L43 -> -32.448 | N43: =M43*1.04 -> -33.74592 | O43: =N43 -> -33.74592 | P43: =O43 -> -33.74592 | Q43: =P43*1.04 -> -35.095757
B44: Net Block | C44: =C39-SUM(C40:C43) -> 866 | D44: =D39-SUM(D40:D43) -> 865 | E44: =E39-SUM(E40:E43) -> 798 | F44: =F39-SUM(F40:F43) -> 648 | G44: =G39-SUM(G40:G43) -> 729 | H44: =H39-SUM(H40:H43) -> 813.24 | I44: =I39-SUM(I40:I43) -> 897.48 | J44: =J39-SUM(J40:J43) -> 981.72 | ... Q44: =Q39-SUM(Q40:Q43) -> 1612.6493
B46: Furniture & Fixtures
B47: Opening Gross Block | C47: 2149 | D47: =C52 -> 2278 | E47: =D52 -> 2303 | F47: =E52 -> 2326 | G47: =F52 -> 2340 | H47: =G52 -> 2438 | I47: =H52 -> 2539.92 | J47: =I52 -> 2641.84 | K47: =J52 -> 2743.76 | ... Q47: =P52 -> 3392.4604
...

Sheet BS items 
B2: Infosys Limited
M6: (unless otherwise mentioned - % on Revenue) | Q6: (INR in Crores)
B7: Balance Sheet Items
B8: Particulars | D8: =FAS!C8 -> 2022 | E8: =FAS!D8 -> 2023 | F8: =FAS!E8 -> 2024 | G8: =FAS!F8 -> 2025 | H8: =FAS!G8 -> 2026 | I8: =FAS!H8 -> 2027 | J8: =FAS!I8 -> 2028 | K8: =FAS!J8 -> 2029 | ... R8: =FAS!Q8 -> 2036
D9: Audited | E9: Audited | F9: Audited | G9: Audited | H9: Audited | I9: Estimated | J9: Projected | K9: Projected | L9: Projected | M9: Projected | N9: Projected | O9: Projected | P9: Projected | Q9: Projected | R9: Projected
B10: ASSETS
B12: ='Balance Sheet'!B12:C12 -> Non-Current Assets
C13: Investments | D13: ='BS Input'!D18 -> 13651 | E13: ='BS Input'!E18 -> 12569 | F13: ='BS Input'!F18 -> 11708 | G13: ='BS Input'!G18 -> 11059 | H13: ='BS Input'!H18 -> 8930 | I13: ='Revenue Buildup'!H$15*'BS items '!I14 -> 15344.305 | J13: ='Revenue Buildup'!I$15*'BS items '!J14 -> 16806.434 | K13: ='Revenue Buildup'!J$15*'BS items '!K14 -> 18254.048 | L13: ='Revenue Buildup'!K$15*'BS items '!L14 -> 19661.282 | M13: ='Revenue Buildup'!L$15*'BS items '!M14 -> 21001.172 | N13: ='Revenue Buildup'!M$15*'BS items '!N14 -> 22246.385 | O13: ='Revenue Buildup'!N$15*'BS items '!O14 -> 23370.009 | P13: ='Revenue Buildup'!O$15*'BS items '!P14 -> 24346.368 | ... R13: ='Revenue Buildup'!Q$15*'BS items '!R14 -> 25765.673
D14: =D13/'P&L Input'!C$11 -> 0.11222367 | E14: =E13/'P&L Input'!D$11 -> 0.085639142 | F14: =F13/'P&L Input'!E$11 -> 0.076189237 | G14: =G13/'P&L Input'!F$11 -> 0.067850788 | H14: =H13/'P&L Input'!G$11 -> 0.049986006 | I14: =AVERAGE(D14:H14) -> 0.07837777 | J14: =I14 -> 0.07837777 | K14: =J14 -> 0.07837777 | L14: =K14 -> 0.07837777 | M14: =L14 -> 0.07837777 | N14: =M14 -> 0.07837777 | O14: =N14 -> 0.07837777 | P14: =O14 -> 0.07837777 | Q14: =P14 -> 0.07837777 | R14: =Q14 -> 0.07837777
C15: Other financial assets | D15: ='BS Input'!D20 -> 1460 | E15: ='BS Input'!E20 -> 2798 | F15: ='BS Input'!F20 -> 3105 | G15: ='BS Input'!G20 -> 3511 | H15: ='BS Input'!H20 -> 2776 | I15: ='Revenue Buildup'!H$15*'BS items '!I16 -> 3459.4135 | J15: ='Revenue Buildup'!I$15*'BS items '!J16 -> 3789.0542 | K15: ='Revenue Buildup'!J$15*'BS items '!K16 -> 4115.4226 | L15: ='Revenue Buildup'!K$15*'BS items '!L16 -> 4432.6872 | M15: ='Revenue Buildup'!L$15*'BS items '!M16 -> 4734.7688 | N15: ='Revenue Buildup'!M$15*'BS items '!N16 -> 5015.5053 | O15: ='Revenue Buildup'!N$15*'BS items '!O16 -> 5268.8293 | P15: ='Revenue Buildup'!O$15*'BS items '!P16 -> 5488.9519 | ... R15: ='Revenue Buildup'!Q$15*'BS items '!R16 -> 5808.9379
D16: =D15/'P&L Input'!C$11 -> 0.012002532 | E16: =E15/'P&L Input'!D$11 -> 0.019064231 | F16: =F15/'P&L Input'!E$11 -> 0.020205635 | G16: =G15/'P&L Input'!F$11 -> 0.021541199 | H16: =H15/'P&L Input'!G$11 -> 0.015538763 | I16: =AVERAGE(D16:H16) -> 0.017670472 | J16: =I16 -> 0.017670472 | K16: =J16 -> 0.017670472 | L16: =K16 -> 0.017670472 | M16: =L16 -> 0.017670472 | N16: =M16 -> 0.017670472 | O16: =N16 -> 0.017670472 | P16: =O16 -> 0.017670472 | Q16: =P16 -> 0.017670472 | R16: =Q16 -> 0.017670472
C17: Deferred Tax Assets(net) | D17: ='BS Input'!D21 -> 1212 | E17: ='BS Input'!E21 -> 1245 | F17: ='BS Input'!F21 -> 454 | G17: ='BS Input'!G21 -> 1108 | H17: ='BS Input'!H21 -> 2264 | I17: ='Revenue Buildup'!H$15*'BS items '!I18 -> 1600.3226 | J17: ='Revenue Buildup'!I$15*'BS items '!J18 -> 1752.8142 | K17: ='Revenue Buildup'!J$15*'BS items '!K18 -> 1903.792 | L17: ='Revenue Buildup'!K$15*'BS items '!L18 -> 2050.5584 | M17: ='Revenue Buildup'!L$15*'BS items '!M18 -> 2190.3012 | N17: ='Revenue Buildup'!M$15*'BS items '!N18 -> 2320.1698 | O17: ='Revenue Buildup'!N$15*'BS items '!O18 -> 2437.3573 | P17: ='Revenue Buildup'!O$15*'BS items '!P18 -> 2539.1859 | ... R17: ='Revenue Buildup'!Q$15*'BS items '!R18 -> 2687.2112
D18: =D17/'P&L Input'!C$11 -> 0.0099637458 | E18: =E17/'P&L Input'!D$11 -> 0.0084828333 | F18: =F17/'P&L Input'!E$11 -> 0.0029543828 | G18: =G17/'P&L Input'!F$11 -> 0.0067979631 | H18: =H17/'P&L Input'!G$11 -> 0.012672824 | I18: =AVERAGE(D18:H18) -> 0.0081743498 | J18: =I18 -> 0.0081743498 | K18: =J18 -> 0.0081743498 | L18: =K18 -> 0.0081743498 | M18: =L18 -> 0.0081743498 | N18: =M18 -> 0.0081743498 | O18: =N18 -> 0.0081743498 | P18: =O18 -> 0.0081743498 | Q18: =P18 -> 0.0081743498 | R18: =Q18 -> 0.0081743498
